Workbook

Sheet Cover
A1: KẾT QUẢ TỔNG HỢP KIỂM THỬ PHẦN MỀM
A2: Dự án: SHOPCART_2025 – MERN Stack E-Commerce
A3: Môn học: Đảm bảo chất lượng phần mềm (SQA)
B5: Mã dự án: | C5: SHOPCART_2025
B6: Phiên bản sản phẩm: | C6: v1.0
B7: Ngày hoàn thành: | C7: 09/05/2026
A9: DANH SÁCH THÀNH VIÊN NHÓM
B10: Họ và tên | C10: MSSV | D10: Vai trò | E10: Module phụ trách
B11: Nguyễn Minh Tiến | C11: K23DTCN215 | D11: Trưởng nhóm | E11: Module Xác thực & Bảo mật (AUTH)
B12: Phạm Minh Tiến | C12: K23DTCN213 | D12: Thành viên | E12: Module Sản phẩm (PRODUCT)
B13: Phạm Văn Nhật | C13: K23DTCN176 | D13: Thành viên | E13: Module Tìm kiếm (SEARCH)
B14: Nguyễn Thị Thanh Thảo | C14: K23DTCN207 | D14: Thành viên | E14: Module Giỏ hàng & Đơn hàng (CART/ORDER)
B15: Hồ Thân Chính | C15: K23DTCN086 | D15: Thành viên | E15: Module Đánh giá & Dashboard (REVIEW)

Sheet Table of Contents
A1: TABLE OF CONTENTS
A3: I | B3: PHẦN 1: CÔNG VIỆC CHUNG CỦA NHÓM
A4: 1 | B4: Mô tả hệ thống SHOPCART_2025 | C4: Phần 1 Công việc chung
A5: 2 | B5: SRS Review Checklist (Nhóm) | C5: Phần 1 SRS Review Checklist
A6: 3 | B6: Review Kế hoạch Test (Nhóm) | C6: Phần 1 Review kế hoạch test
A7: 4 | B7: Code Review Checklist (Nhóm) | C7: Phần 1 Code Review Checklist
A8: 5 | B8: Review Kịch bản Test (Nhóm) | C8: Phần 1 Review kịch bản test
A9: II | B9: PHẦN 2: KẾT QUẢ TỪNG THÀNH VIÊN
A10: 2.1 | B10: Nguyễn Minh Tiến – UC Xác thực & Bảo mật | C10: Nguyễn Minh Tiến - UC AUTH
B11: Nguyễn Minh Tiến – API Testing | C11: Nguyễn Minh Tiến - API Testing
B12: Nguyễn Minh Tiến – Kiểm thử tự động | C12: Nguyễn Minh Tiến - Automation
B13: Nguyễn Minh Tiến – Kiểm thử hiệu năng | C13: Nguyễn Minh Tiến - Performance
B14: Nguyễn Minh Tiến – Review cá nhân | C14: Nguyễn Minh Tiến - Review
B15: Nguyễn Minh Tiến – Đánh giá kết quả | C15: Nguyễn Minh Tiến - Đánh giá KQ
A16: 2.2 | B16: Phạm Minh Tiến – UC Sản phẩm | C16: Phạm Minh Tiến - UC PROD
B17: Phạm Minh Tiến – API Testing | C17: Phạm Minh Tiến - API Testing
B18: Phạm Minh Tiến – Kiểm thử tự động | C18: Phạm Minh Tiến - Automation
B19: Phạm Minh Tiến – Kiểm thử hiệu năng | C19: Phạm Minh Tiến - Performance
B20: Phạm Minh Tiến – Review cá nhân | C20: Phạm Minh Tiến - Review
B21: Phạm Minh Tiến – Đánh giá kết quả | C21: Phạm Minh Tiến - Đánh giá KQ
A22: 2.3 | B22: Phạm Văn Nhật – UC Tìm kiếm | C22: Phạm Văn Nhật - UC SRCH
B23: Phạm Văn Nhật – API Testing | C23: Phạm Văn Nhật - API Testing
B24: Phạm Văn Nhật – Kiểm thử tự động | C24: Phạm Văn Nhật - Automation
B25: Phạm Văn Nhật – Kiểm thử hiệu năng | C25: Phạm Văn Nhật - Performance
B26: Phạm Văn Nhật – Review cá nhân | C26: Phạm Văn Nhật - Review
B27: Phạm Văn Nhật – Đánh giá kết quả | C27: Phạm Văn Nhật - Đánh giá KQ
A28: 2.4 | B28: Nguyễn Thị Thanh Thảo – UC Giỏ hàng & Đơn | C28: Nguyễn Thị Thanh Thảo - UC CART
B29: Nguyễn Thị Thanh Thảo – API Testing | C29: Nguyễn Thị Thanh Thảo - API Testing
B30: Nguyễn Thị Thanh Thảo – Kiểm thử tự động | C30: Nguyễn Thị Thanh Thảo - Automation
B31: Nguyễn Thị Thanh Thảo – Kiểm thử hiệu năng | C31: Nguyễn Thị Thanh Thảo - Performance
B32: Nguyễn Thị Thanh Thảo – Review cá nhân | C32: Nguyễn Thị Thanh Thảo - Review
B33: Nguyễn Thị Thanh Thảo – Đánh giá kết quả | C33: Nguyễn Thị Thanh Thảo - Đánh giá KQ
A34: 2.5 | B34: Hồ Thân Chính – UC Đánh giá & Dashboard | C34: Hồ Thân Chính - UC REVW
B35: Hồ Thân Chính – API Testing | C35: Hồ Thân Chính - API Testing
B36: Hồ Thân Chính – Kiểm thử tự động | C36: Hồ Thân Chính - Automation
B37: Hồ Thân Chính – Kiểm thử hiệu năng | C37: Hồ Thân Chính - Performance
B38: Hồ Thân Chính – Review cá nhân | C38: Hồ Thân Chính - Review
B39: Hồ Thân Chính – Đánh giá kết quả | C39: Hồ Thân Chính - Đánh giá KQ
A40: III | B40: Nhóm – Review Test Plan | C40: Nhóm - Review Test Plan

Sheet Phần 1 Công việc chung
A2: I. CÔNG VIỆC CHUNG CỦA NHÓM
B4: 1. Mô tả hệ thống
B5: 1.1. Giới thiệu về hệ thống
B6: SHOPCART_2025 là ứng dụng thương mại điện tử full-stack được xây dựng trên nền tảng MERN Stack (MongoDB, Express.js, React, Node.js), cho phép người mua sắm duyệt và đặt hàng trực tuyến, trong khi người bán có thể quản lý sản phẩm và theo dõi đơn hàng thông qua dashboard. Hệ thống hỗ trợ hai vai trò người dùng: Customer (khách hàng) và Seller (người bán), với xác thực JWT và mã hóa bcrypt.
B8: 1.2. Công nghệ sử dụng
B9: Frontend: React 18
B10: Backend: Node.js 18, Express.js 4
B11: Database: MongoDB
B12: State Management: Redux Toolkit, lưu token trong Redux store
B13: Bảo mật: authMiddleware.js (xác thực JWT), bcrypt hash password
B15: 1.3. Chức năng chính của hệ thống
B16: Module Xác thực (AUTH): | C16: Đăng ký/đăng nhập Customer và Seller, xác thực JWT, quản lý profile
B17: Module Sản phẩm (PRODUCT): | C17: CRUD sản phẩm (thêm, xem, sửa, xóa), upload ảnh, quản lý tồn kho
B18: Module Tìm kiếm (SEARCH): | C18: Tìm kiếm theo từ khóa, lọc theo danh mục/giá, sắp xếp
B19: Module Giỏ hàng & Đơn (CART/ORDER): | C19: Quản lý giỏ hàng, wishlist, tạo/theo dõi đơn hàng, snapshot giá
B20: Module Đánh giá & Dashboard (REVIEW): | C20: Đánh giá sản phẩm, dashboard thống kê cho seller
B22: 1.4. Hiện trạng đảm bảo chất lượng của hệ thống
B23: 1. Thời điểm khi mới nhận phần mềm:
B24: Phần mềm được bàn giao dưới dạng mã nguồn MERN stack chưa có tài liệu SQA
B25: Chưa có tài liệu đặc tả yêu cầu (SRS) chi tiết
B26: Không có kế hoạch kiểm thử hay tài liệu testcase từ đội phát triển
B27: authMiddleware.js được viết nhưng không được kết nối vào bất kỳ route nào
B28: Không có input validation middleware, endpoint trả về HTTP 500 khi thiếu dữ liệu
B30: 2. Hiện trạng tại thời điểm báo cáo:
B31: Tài liệu SRS v1.0 được xây dựng đầy đủ với 24 use cases
B32: Test Plan chi tiết 11 phần, 6 tuần, 6 loại kiểm thử, 9 công cụ
B33: Tổng 109 test cases trên 5 modules, kết quả: 76 Pass / 33 Fail
B34: Phát hiện 25 bugs, trong đó 3 lỗi Critical S1 về bảo mật cần sửa ngay
B35: 4 checklist review hoàn chỉnh (SRS, Code, Test Plan, Test Case)

Sheet Phần 1 SRS Review Checklist
A1: SRS Review Checklist
A3: Mã dự án | B3: SHOPCART_2025
A4: Phiên bản sản phẩm | B4: v1.0
A5: Phân hệ / Module | B5: Toàn hệ thống SHOPCART_2025
A6: Lần xem xét | B6: 1
A7: Người review | B7: Hồ Thân Chính (K23DTCN086)
A8: Ngày review | B8: 25/04/2026
A9: Độ lớn sản phẩm | B9: 24 use cases, 5 modules
A10: Nguồn lực (MH) | B10: 8
A12: Câu hỏi | B12: Có | C12: Không | D12: N/A | E12: Ghi chú | F12: Điều kiện
A13: Kiểm soát tài liệu
A14: Tài liệu có tuân thủ theo yêu cầu kiểm soát tài liệu không: | F14: Bắt buộc
A15: Mẫu tài liệu có phải là mẫu mới nhất không? | B15: x | F15: Bắt buộc
A16: Trang tiêu đề có bao gồm đủ tên tài liệu, phiên bản, tên trường, mã dự án và thời gian ban hành không? | B16: x | F16: Bắt buộc
A17: Đầu và cuối trang có bao gồm tên, phiên bản của tài liệu không? | B17: x | F17: Bắt buộc
A18: Đánh số trang có theo đúng quy định: số thứ tự/tổng số trang? | B18: x | F18: Bắt buộc
A19: Trang ký có bao gồm đủ Người review & Người phê duyệt không? | B19: x | F19: Bắt buộc
A20: Có bảng theo dõi lịch sử thay đổi không? | B20: x | F20: Bắt buộc
A21: Đối với phiên bản tài liệu > v1.0: Các nội dung ghi nhận thay đổi có đầy đủ và đúng không? | E21: x | F21: Bắt buộc
A22: Giới thiệu chung
A23: Có nêu rõ mục đích của tài liệu không? | B23: x | F23: Bắt buộc
A24: Phạm vi hệ thống có được mô tả rõ ràng không? | B24: x
A25: Các khái niệm và thuật ngữ có được định nghĩa đầy đủ không? | B25: x | F25: Bắt buộc
A26: Có liệt kê các tài liệu tham khảo không? | B26: x
A27: Tên tài liệu tham chiếu | B27: x
A28: Ngày phát hành | B28: x
A29: Nguồn | B29: x
A30: Có mô tả giới hạn của tài liệu không? | B30: x | F30: Bắt buộc
A31: Có mô tả tổ chức của tài liệu không? | B31: x | F31: Bắt buộc
A32: Mô tả tổng thể
A33: Có xác định ngữ cảnh và điều kiện sử dụng của hệ thống không? | B33: x | F33: Bắt buộc
A34: Có liệt kê các chức năng sản phẩm trong tài liệu không? | B34: x | F34: Bắt buộc
A35: Có được phân nhóm một cách hợp lý? | B35: x
A36: Có được mô tả một cách chính xác không? | B36: x
A37: Danh sách nhóm người / người sử dụng có được đề cập không? | B37: x
A38: Vai trò của nhóm người / người sử dụng có được ghi nhận không? | B38: x
A39: Có mô hình / Sơ đồ tổng thể hệ thống không? | B39: x | E39: Có sơ đồ kiến trúc 3-tier MERN
A40: Có mô tả đặc điểm người sử dụng không? | B40: x | F40: Bắt buộc
A41: Có mô tả các ràng buộc đối với hệ thống không? | B41: x
A42: Có các giả thiết và phụ thuộc không? | B42: x | E42: Được thể hiện ở phần Phạm vi
...

Sheet Phần 1 Review kế hoạch test
A1: Checklist Review Kế hoạch test
A3: Mã dự án | B3: SHOPCART_2025
A4: Phiên bản sản phẩm | B4: v1.0
A5: Phân hệ / Module | B5: Toàn hệ thống
A6: Lần xem xét | B6: 1
A7: Người review | B7: Phạm Văn Nhật (K23DTCN176)
A8: Ngày review | B8: 27/04/2026
A9: Độ lớn sản phẩm | B9: 24 API endpoints, 6 loại kiểm thử
A10: Nguồn lực (MH) | B10: 8
A12: Câu hỏi | B12: Có | C12: Không | D12: N/A | E12: Ghi chú | F12: Điều kiện
A13: Kiểm soát tài liệu
A14: Tài liệu có tuân thủ yêu cầu kiểm soát tài liệu không? | B14: x | F14: Bắt buộc
A15: Mẫu tài liệu có phải mẫu mới nhất không? | B15: x | F15: Bắt buộc
A16: Trang tiêu đề có đầy đủ tên tài liệu, phiên bản, mã dự án không? | B16: x | F16: Bắt buộc
A17: Đánh số trang đúng quy định không? | B17: x | F17: Bắt buộc
A18: Trang ký có đủ Người lập, Người review & Người phê duyệt không? | B18: x | F18: Bắt buộc
A19: Có Bảng ghi nhận thay đổi không? | B19: x | F19: Bắt buộc
A20: Có liệt kê các tài liệu liên quan không? | B20: x | F20: Bắt buộc
A21: Thông tin chung
A22: Giới thiệu chung về mục đích và cấu trúc tài liệu? | B22: x | F22: Bắt buộc
A23: Tóm tắt mục tiêu và phạm vi kiểm thử? | B23: x | F23: Bắt buộc
A24: Kế hoạch test
A25: Xác định rõ sản phẩm cần test (in-scope/out-of-scope) chưa? | B25: x | F25: Bắt buộc
A26: Unit Testing | B26: x
A27: Integration Testing | B27: x
A28: System Testing | B28: x
A29: API Testing | B29: x
A30: Security Testing | B30: x
A31: Performance Testing | B31: x
A32: Có liệt kê rủi ro ảnh hưởng đến việc kiểm thử không? | B32: x | F32: Bắt buộc
A33: Phương án khắc phục và phòng ngừa | B33: x | F33: Bắt buộc
A34: Mức độ ảnh hưởng | B34: x | F34: Bắt buộc
A35: Có liệt kê ràng buộc cho test không? | B35: x
A36: Các yêu cầu cho test hệ thống? | B36: x | F36: Bắt buộc
A37: Có mô tả môi trường test, công cụ test không? | B37: x | F37: Bắt buộc
A38: Có xác định sản phẩm của việc test không? | B38: x | F38: Bắt buộc
A39: Lịch test có phù hợp với lịch phát triển không? | B39: x | F39: Bắt buộc
A40: Có xác định điều kiện làm dừng việc test không? | B40: x | F40: Bắt buộc
A41: Nhân sự: Có xác định rõ trách nhiệm từng thành viên không? | B41: x | F41: Bắt buộc
A42: Có xác định nguồn lực sử dụng cho giai đoạn test không? | B42: x | F42: Bắt buộc
...

Sheet Phần 1 Code Review Checklist
A1: Code Review Checklist
A3: Mã dự án | B3: SHOPCART_2025
A4: Phiên bản sản phẩm | B4: v1.0
A5: Module | B5: Toàn hệ thống – 4 controllers, 4 schemas
A6: Người review | B6: Nguyễn Thị Thanh Thảo (K23DTCN207)
A7: Ngày review | B7: 26/04/2026
A8: Độ lớn sản phẩm | B8: Ước lượng 2000+ dòng code
A9: Nguồn lực (MH) | B9: 8
A11: Câu hỏi | B11: Có | C11: Không | D11: N/A | E11: Ghi chú
A12: Tổng quan
A13: Code có được viết tốt không (về mặt hình thức)? Đọc có dễ hiểu không? | B13: x
A14: Các ghi chú và chuẩn lập trình
A15: Code có thực hiện theo đúng chuẩn lập trình không? | B15: x
A16: Tên biến | B16: x
A17: Căn lề (indentation) | B17: x
A18: Kiểu dấu ngoặc | B18: x
A19: Các file source có đầy đủ header không? | C19: x | D19: Không có copyright header
A20: Các khai báo biến có được ghi chú đúng cách không? | B20: x
A21: Toàn bộ các functions, methods có được ghi chú lại không? | C21: x | D21: Thiếu JSDoc cho controller functions
A22: Các đoạn thuật toán phức tạp có được ghi chú đầy đủ không? | B22: x
A23: Các đoạn code bị hủy bỏ có được giải thích không? | C23: x | D23: Không có code bị comment out
A24: Các ghi chú có rõ ràng và đúng không? | B24: x
A25: Tên hàm/class có nói lên chức năng không? | B25: x
A26: Xử lý lỗi
A27: Có xử lý lỗi (try-catch) trong các hàm async không? | B27: x
A28: Các trường hợp ngoại lệ có được xử lý không? | C28: x | D28: Thiếu validation middleware; 500 thay vì 400
A29: Các hàm gọi đến có được thông báo khi có lỗi không? | B29: x
A30: Bảo mật
A31: authMiddleware.js có được áp dụng vào các route bảo vệ không? | C31: x | D31: CRITICAL: authMiddleware tồn tại nhưng KHÔNG mount vào route nào
A32: Input validation có được thực hiện trước khi xử lý không? | C32: x | D32: Không có validation middleware; thiếu hoàn toàn
A33: Regex search có được escape input không? | C33: x | D33: BUG_SRCH_012: Regex injection vulnerability
A34: Authorization ownership có được kiểm tra không? | C34: x | D34: BUG_PROD_003, BUG_AUTH_002: Thiếu kiểm tra ownership
A35: Quản lý tài nguyên
A36: Database connections có được đóng đúng cách không? | B36: x
A37: Mongoose connections được quản lý qua mongoose.connect()? | B37: x
A38: Performance
A39: Code đã được viết tối ưu chưa? | B39: x
A40: Có sử dụng index trên MongoDB không? | C40: x | D40: Thiếu index cho các trường search phổ biến
A41: Các hàm
A42: Các biến của hàm có được xác minh rõ ràng không? | B42: x
...

Sheet Phần 1 Review kịch bản test
A1: Checklist Review Kịch bản test
A3: Mã dự án | B3: SHOPCART_2025
A4: Phiên bản sản phẩm | B4: v1.0
A5: Module | B5: 5 modules: AUTH, PROD, SRCH, CART, REVW
A6: Người review | B6: Phạm Minh Tiến (K23DTCN213)
A7: Ngày review | B7: 28/04/2026
A8: Độ lớn sản phẩm | B8: 109 test cases tổng cộng
A9: Nguồn lực (MH) | B9: 8
A11: Câu hỏi | B11: Có | C11: Không | D11: N/A | E11: Ghi chú | F11: Điều kiện
A12: Kiểm soát tài liệu
A13: Tài liệu có tuân thủ yêu cầu kiểm soát tài liệu không? | B13: x | F13: Bắt buộc
A14: Mẫu tài liệu có phải mẫu mới nhất không? | B14: x | F14: Bắt buộc
A15: Trang tiêu đề đầy đủ thông tin không? | B15: x | F15: Bắt buộc
A16: Đánh số trang đúng không? | B16: x | F16: Bắt buộc
A17: Có Bảng ghi nhận thay đổi không? | B17: x | F17: Bắt buộc
A18: Có liệt kê tài liệu liên quan không? | B18: x | F18: Bắt buộc
A19: Kiểm tra các Test Case
A20: Có ID duy nhất cho từng Test Case không? | B20: x | F20: Bắt buộc
A21: Test case có tham chiếu đến yêu cầu (UC/API) không? | B21: x | F21: Bắt buộc
A22: Các bước thực hiện được mô tả đầy đủ không? | B22: x | F22: Bắt buộc
A23: Đầu vào (dữ liệu test) được cung cấp không? | B23: x | F23: Bắt buộc
A24: Kết quả mong đợi cho mỗi đầu vào? | B24: x | F24: Bắt buộc
A25: Có tiêu chí so sánh kết quả mong đợi và thực tế không? | B25: x
A26: Điều kiện hợp lệ (Valid cases) | B26: x | F26: Bắt buộc
A27: Điều kiện không hợp lệ (Invalid/Negative) | B27: x | F27: Bắt buộc
A28: Có mô tả ràng buộc giữa các Test Case không? | C28: x | E28: Chưa có mô tả dependency giữa TCs | F28: Bắt buộc
A29: Xem xét các thủ tục test
A30: Thủ tục có mô tả điều kiện bắt đầu cho mỗi TC không? | B30: x
A31: Có mô tả phương pháp setup môi trường test không? | C31: x | E31: Chưa có hướng dẫn cài đặt môi trường trong TC
A32: Kết quả Pass/Fail có được ghi nhận đầy đủ không? | B32: x | F32: Bắt buộc
A33: Bug report có liên kết với TC fail không? | B33: x | F33: Bắt buộc
A34: TỔNG HỢP | B34: 17 | C34: 2 | D34: 0
A36: * Nhận xét
A37: Tài liệu Checklist phiên bản v1.0 đã đáp ứng phần lớn các tiêu chí kiểm soát và nội dung bắt buộc. Các mục chính đều được trình bày đầy đủ, rõ ràng, nhất quán.
A39: * Đề xuất
A40: Bổ sung các điểm còn thiếu ở phiên bản tiếp theo để hoàn thiện hơn.
A42: Kết quả
A43: [x] Đạt [ ] Xem xét lại [ ] Khác

Sheet Nguyễn Minh Tiến - UC AUTH
A1: Function Name | C1: UC – Xác thực & Bảo mật (AUTH)
A2: Tester Name | C2: Nguyễn Minh Tiến
A3: Test Result | C3: Web (Chrome) | D3: N/A (Desktop)
A4: Total | C4: 18
A5: Passed | C5: 14
A6: Failed | C6: 4
A7: Not Run | C7: 0
A10: ID | B10: Summary | C10: Steps | D10: Expected Output | E10: Hình ảnh mô tả | F10: Test Results | G10: Đánh giá mức độ lỗi | H10: Mô tả lỗi
F11: Web (Chrome)
A12: I. Trang đăng ký khách hàng (/Customerregister)
A13: 1. Kiểm tra giao diện trang đăng ký
A14: AUTH_01 | B14: Hiển thị đúng giao diện trang đăng ký Customer | C14: 1. Mở trình duyệt Chrome, truy cập http://localhost:3000 2. Nhấn nút Sign In/Register trên Navbar màu tím (#4d1c9c) 3. Chọn 'Customer Register' từ menu dropdown 4. Quan sát trang /Customerregister | D14: 1. Trang hiển thị layout 2 cột: - Cột trái (5/12): form đăng ký với tiêu đề 'Customer Register' - Cột phải (7/12): ảnh nền từ pexels (mua sắm) 2. Form có đủ 3 trường: 'User Name', 'Email', 'Password' 3. Trường Password có icon mắt để toggle hiển thị/ẩn mật khẩu 4. Nút Submit màu tím (LightPurpleButton) 5. Link 'Already have an account? Login' ở cuối form | F14: Pass
A15: AUTH_02 | B15: Đăng ký Customer thành công với dữ liệu hợp lệ | C15: 1. Truy cập http://localhost:3000/Customerregister 2. Nhập 'User Name': Nguyen Van Test 3. Nhập 'Email': customer_test01@gmail.com 4. Nhập 'Password': Test@12345 5. Nhấn nút 'Customer Register' | D15: 1. Frontend gọi POST /api/CustomerRegister với body { name, email, password, role: 'Customer' } 2. Server trả về HTTP 200, response chứa { _id, name, email, role, token } – password KHÔNG có trong response 3. Redux state currentUser được set, currentRole = 'Customer' 4. Navbar cập nhật: hiển thị Avatar và tên người dùng thay vì nút Sign In 5. Trang chuyển hướng về http://localhost:3000/ | F15: Pass
A16: AUTH_03 | B16: Đăng ký Customer với email đã tồn tại | C16: 1. Đảm bảo email customer_test01@gmail.com đã đăng ký 2. Truy cập lại /Customerregister 3. Nhập 'User Name': Ten Khac 4. Nhập 'Email': customer_test01@gmail.com (đã tồn tại) 5. Nhập 'Password': AnyPass@123 6. Nhấn 'Customer Register' | D16: 1. Server trả về HTTP 200 với { message: 'Email already exists' } 2. Giao diện hiển thị Popup thông báo 'Email already exists' 3. Người dùng vẫn ở trang /Customerregister 4. Không tạo tài khoản mới | F16: Pass
A17: 2. Kiểm tra validation phía client (inline error)
A18: AUTH_04 | B18: Submit form đăng ký khi bỏ trống trường User Name | C18: 1. Truy cập /Customerregister 2. Bỏ trống trường 'User Name' 3. Nhập Email và Password hợp lệ 4. Nhấn nút 'Customer Register' | D18: 1. Trường 'User Name' đổi sang trạng thái lỗi (TextField error=true – viền đỏ) 2. Không gọi API đến server 3. Người dùng vẫn ở trang đăng ký | F18: Pass
A19: AUTH_05 | B19: Submit form khi bỏ trống Email | C19: 1. Truy cập /Customerregister 2. Nhập User Name và Password hợp lệ 3. Bỏ trống trường 'Email' 4. Nhấn nút 'Customer Register' | D19: 1. Trường 'Email' hiển thị lỗi (emailError = true, viền đỏ MUI) 2. Không gọi API 3. Loader không xuất hiện | F19: Pass
A20: AUTH_06 | B20: Submit form khi bỏ trống Password | C20: 1. Truy cập /Customerregister 2. Nhập User Name và Email hợp lệ 3. Bỏ trống trường 'Password' 4. Nhấn nút 'Customer Register' | D20: 1. Trường 'Password' hiển thị lỗi (passwordError = true, viền đỏ) 2. Không gọi API | F20: Pass
A21: AUTH_07 | B21: Toggle hiển thị/ẩn mật khẩu | C21: 1. Truy cập /Customerregister 2. Nhập vào trường 'Password': TestPass123 3. Nhấn icon mắt (Visibility/VisibilityOff) bên phải trường Password 4. Quan sát trạng thái hiển thị | D21: 1. Sau lần nhấn đầu: mật khẩu hiển thị dạng text rõ (type='text') 2. Sau lần nhấn thứ 2: mật khẩu ẩn lại (type='password', hiển thị dấu •••) 3. Nội dung mật khẩu không thay đổi | F21: Pass
A22: II. Trang đăng nhập khách hàng (/Customerlogin)
A23: 1. Kiểm tra chức năng đăng nhập
A24: AUTH_08 | B24: Đăng nhập Customer thành công | C24: 1. Truy cập http://localhost:3000/Customerlogin 2. Nhập 'Email': customer_test01@gmail.com 3. Nhập 'Password': Test@12345 4. Nhấn nút 'Customer Login' | D24: 1. POST /api/CustomerLogin trả về HTTP 200 2. Response: { _id, name, email, role: 'Customer', token (JWT 10 ngày) } 3. Redux: currentUser set, isLoggedIn = true, currentRole = 'Customer' 4. Navbar: hiển thị Avatar (chữ cái đầu tên), icon giỏ hàng (ShoppingCartIcon) với Badge 5. Chuyển hướng về trang chủ / | F24: Pass
A25: AUTH_09 | B25: Đăng nhập với mật khẩu sai | C25: 1. Truy cập /Customerlogin 2. Nhập 'Email': customer_test01@gmail.com 3. Nhập 'Password': SaiMatKhau999 4. Nhấn 'Customer Login' | D25: 1. Server trả về { message: 'Invalid password' } 2. Popup hiển thị thông báo 'Invalid password' 3. Loader biến mất 4. Không cấp token, không chuyển trang | F25: Pass
A26: AUTH_10 | B26: Đăng nhập với email không tồn tại | C26: 1. Truy cập /Customerlogin 2. Nhập 'Email': khongtontai_xyz@gmail.com 3. Nhập 'Password': BatKy@123 4. Nhấn 'Customer Login' | D26: 1. Server trả về { message: 'User not found' } 2. Popup hiển thị 'User not found' 3. Người dùng vẫn ở trang login | F26: Pass
A27: AUTH_11 | B27: Đăng nhập khi bỏ trống Email và Password | C27: 1. Truy cập /Customerlogin 2. Để trống cả Email và Password 3. Nhấn 'Customer Login' | D27: 1. Cả hai trường chuyển sang trạng thái lỗi (viền đỏ) 2. Không gọi API 3. Loader không xuất hiện | F27: Pass
A28: 2. Kiểm tra bảo mật đăng nhập
A29: AUTH_12 | B29: Brute-force: Thử đăng nhập sai liên tiếp 10 lần | C29: 1. Truy cập /Customerlogin 2. Nhập Email hợp lệ: customer_test01@gmail.com 3. Nhập Password sai, nhấn Login 4. Lặp lại 10 lần liên tiếp 5. Quan sát phản hồi hệ thống sau mỗi lần | D29: 1. Sau 5 lần thất bại liên tiếp, hệ thống khóa tạm thời hoặc hiển thị CAPTCHA 2. Hoặc server trả về HTTP 429 Too Many Requests 3. Có cơ chế rate-limiting bảo vệ endpoint /api/CustomerLogin | F29: Fail | G29: Nghiêm trọng | H29: Không có rate limiting. Hệ thống trả về { message: 'Invalid password' } sau mỗi lần thử mà không giới hạn số lần. Endpoint dễ bị tấn công brute-force.
A30: III. Trang đăng ký / đăng nhập Seller
A31: 1. Đăng ký Seller (/Sellerregister)
A32: AUTH_13 | B32: Hiển thị đúng form đăng ký Seller | C32: 1. Truy cập http://localhost:3000/Sellerregister 2. Quan sát giao diện | D32: 1. Form có 4 trường: 'User Name', 'Shop Name', 'Email', 'Password' 2. Tiêu đề: 'Seller Register' 3. Dòng chú thích: 'Create your own shop by registering as a seller.' 4. Layout 2 cột giống Customer register | F32: Pass
A33: AUTH_14 | B33: Đăng ký Seller với tên shop đã tồn tại | C33: 1. Đảm bảo shop 'Thời Trang ABC' đã tồn tại 2. Truy cập /Sellerregister 3. Nhập Shop Name: Thời Trang ABC (trùng) 4. Nhập các trường còn lại hợp lệ 5. Nhấn 'Seller Register' | D33: 1. Server trả về { message: 'Shop name already exists' } 2. Popup thông báo lỗi hiển thị 3. Không tạo tài khoản mới | F33: Pass
A34: IV. Phân quyền và bảo mật API (Authorization)
A35: 1. Kiểm tra authMiddleware
A36: AUTH_15 | B36: Truy cập API getCartDetail không cần token (lỗ hổng bảo mật) | C36: 1. Mở tab mới trong Chrome, truy cập http://localhost:3000 2. Không đăng nhập 3. Mở DevTools (F12) > Network 4. Gõ vào Console: fetch('http://localhost:5001/api/getCartDetail/ANY_ID').then(r=>r.json()).then(console.log) 5. Quan sát network response | D36: 1. HTTP 401 Unauthorized 2. Response: { message: 'Access denied. No token provided.' } 3. Không trả về dữ liệu giỏ hàng | F36: Fail | G36: Nghiêm trọng | H36: API trả về HTTP 200 và dữ liệu giỏ hàng (hoặc { message: 'No customer found' }) mà không cần token. File authMiddleware.js tồn tại nhưng KHÔNG được mount vào bất kỳ route nào trong route.js. (BUG_AUTH_001 Critical)
A37: AUTH_16 | B37: IDOR: Customer A xem giỏ hàng của Customer B | C37: 1. Đăng nhập Customer A (customer_test01@gmail.com) 2. Mở DevTools Console 3. Lấy _id của Customer B từ URL hoặc source (ví dụ: CUSTOMER_B_ID) 4. Gọi: fetch('http://localhost:5001/api/getCartDetail/CUSTOMER_B_ID').then(r=>r.json()).then(console.log) 5. Quan sát có trả về data của B không | D37: 1. HTTP 403 Forbidden 2. Response: { message: 'Access denied.' } 3. Không trả về dữ liệu giỏ hàng của Customer B | F37: Fail | G37: Nghiêm trọng | H37: API trả về toàn bộ cartDetails của Customer B mà không kiểm tra ownership. Không có so sánh req.user._id vs req.params.id. (BUG_AUTH_002 Critical)
A38: V. Đăng xuất (Logout)
A39: AUTH_17 | B39: Đăng xuất thành công qua menu Avatar | C39: 1. Đăng nhập tài khoản Customer 2. Nhấn vào Avatar (icon tròn) trên Navbar 3. Chọn 'Logout' từ dropdown menu 4. Quan sát trạng thái | D39: 1. Chuyển hướng đến /Logout 2. Redux state reset: currentUser = null, isLoggedIn = false, currentRole = null 3. Navbar hiển thị lại nút 'Sign In' 4. Icon giỏ hàng biến mất hoặc không hiển thị badge số lượng | F39: Pass
A40: AUTH_18 | B40: Token vẫn hợp lệ sau khi đăng xuất (lỗ hổng) | C40: 1. Đăng nhập Customer, mở DevTools > Application > Local Storage 2. Copy giá trị token JWT 3. Nhấn Logout 4. Dùng Postman gửi GET /api/getCartDetail/:id với header Authorization: Bearer <token_đã_đăng_xuất> 5. Quan sát response | D40: 1. HTTP 401 Unauthorized 2. Server từ chối token đã đăng xuất | F40: Fail | G40: Trung bình | H40: Server vẫn chấp nhận token đã đăng xuất. Logout chỉ xóa state Redux phía client, không có cơ chế blacklist/invalidate token phía server.

Sheet Nguyễn Minh Tiến - API Testing
A1: Feature | B1: TestCase ID | C1: Type | D1: Summary | E1: Objective | F1: Test Data | G1: Test Steps | H1: Expected Result | I1: Test Result | J1: Note | K1: Evidence
A2: CustomerRegister | B2: AUTH_API_01 | C2: Functionality | D2: Đăng ký Customer thành công với dữ liệu hợp lệ | E2: Xác nhận API tạo tài khoản Customer mới và trả về JWT token khi gửi đủ dữ liệu hợp lệ | G2: 1. Mở Postman, gửi POST request đến http://localhost:5001/api/CustomerRegister 2. Headers: Content-Type: application/json 3. Body (raw JSON): { "name": "Nguyen Van Test", "email": "customer_test01@gmail.com", "password": "Test@12345", "role": "Customer" } 4. Nhấn Send, quan sát response | H2: 1. HTTP status: 200 OK 2. Response JSON có dạng: {{ "_id": "<ObjectId>", "name": "Nguyen Van Test", "email": "customer_test01@gmail.com", "role": "Customer", "cartDetails": [], "token": "<JWT_token>" }} 3. Trường 'password' KHÔNG xuất hiện trong response | I2: Pass
A3: CustomerRegister | B3: AUTH_API_02 | C3: Validation | D3: Đăng ký với email đã tồn tại | E3: Kiểm tra API trả về message lỗi khi email đã được đăng ký | F3: Email: customer_test01@gmail.com (đã tồn tại) | G3: 1. Gửi POST http://localhost:5001/api/CustomerRegister 2. Body: { "name": "Ten Khac", "email": "customer_test01@gmail.com", "password": "AnyPass@123", "role": "Customer" } 3. Quan sát response | H3: 1. HTTP status: 200 OK 2. Response: {{ "message": "Email already exists" }} 3. Không tạo tài khoản mới | I3: Pass
A4: CustomerRegister | B4: AUTH_API_03 | C4: Validation | D4: Đăng ký thiếu trường password | E4: Kiểm tra server xử lý khi body thiếu trường bắt buộc | G4: 1. Gửi POST http://localhost:5001/api/CustomerRegister 2. Body (thiếu password): { "name": "Test User", "email": "nopassword@gmail.com", "role": "Customer" } 3. Quan sát response | H4: 1. HTTP status: 400 Bad Request 2. Response thông báo lỗi: password là bắt buộc 3. Không tạo tài khoản | I4: Fail | J4: bcrypt.hash(undefined) gây crash → HTTP 500 Internal Server Error. Thiếu validation middleware phía server. Response: {"message": "data and salt arguments required"} hoặc stack trace.
A5: CustomerLogin | B5: AUTH_API_04 | C5: Functionality | D5: Đăng nhập Customer thành công | E5: Xác nhận API trả về JWT token khi credentials hợp lệ | F5: Email: customer_test01@gmail.com, Password: Test@12345 | G5: 1. Gửi POST http://localhost:5001/api/CustomerLogin 2. Headers: Content-Type: application/json 3. Body: { "email": "customer_test01@gmail.com", "password": "Test@12345" } 4. Quan sát response | H5: 1. HTTP status: 200 OK 2. Response JSON: {{ "_id": "<ObjectId>", "name": "Nguyen Van Test", "email": "customer_test01@gmail.com", "role": "Customer", "cartDetails": [...], "token": "eyJhbGciOiJIUzI1NiIsInR5cCI6IkpXVCJ9..." }} 3. Token JWT có thể decode được với payload { userId: <_id> } 4. Trường 'password' KHÔNG có trong response | I5: Pass
A6: CustomerLogin | B6: AUTH_API_05 | C6: Validation | D6: Đăng nhập với mật khẩu sai | E6: Kiểm tra API trả về thông báo lỗi khi password không khớp | G6: 1. Gửi POST http://localhost:5001/api/CustomerLogin 2. Body: { "email": "customer_test01@gmail.com", "password": "SaiMatKhau999" } 3. Quan sát response | H6: 1. HTTP status: 200 OK 2. Response: {{ "message": "Invalid password" }} 3. Không trả về token | I6: Pass
A7: CustomerLogin | B7: AUTH_API_06 | C7: Security | D7: Đăng nhập với email không tồn tại | E7: Kiểm tra API xử lý khi email không có trong database | G7: 1. Gửi POST http://localhost:5001/api/CustomerLogin 2. Body: { "email": "khongtontai_xyz@gmail.com", "password": "BatKy@123" } 3. Quan sát response | H7: 1. HTTP status: 200 OK 2. Response: {{ "message": "User not found" }} 3. Không trả về token | I7: Pass
A8: getCartDetail | B8: AUTH_API_07 | C8: Security | D8: Truy cập getCartDetail không có token (AuthMiddleware bypass) | E8: Kiểm tra authMiddleware có bảo vệ endpoint getCartDetail không | F8: customerId: <ID hợp lệ từ DB> | G8: 1. Gửi GET http://localhost:5001/api/getCartDetail/CUSTOMER_ID 2. KHÔNG thêm header Authorization 3. Quan sát response | H8: 1. HTTP status: 401 Unauthorized 2. Response: {{ "message": "Access denied. No token provided." }} 3. Không trả về dữ liệu giỏ hàng | I8: Fail | J8: HTTP 200 OK, trả về cartDetails đầy đủ của customer. authMiddleware.js import trong route.js nhưng KHÔNG được dùng cho route này. (BUG_AUTH_001 Critical)
A9: CustomerUpdate | B9: AUTH_API_08 | C9: Security | D9: IDOR: Cập nhật giỏ hàng của Customer B bằng ID của B | E9: Kiểm tra API có xác thực ownership trước khi cho phép cập nhật không | F9: CUSTOMER_B_ID: ID của một Customer khác | G9: 1. Đăng nhập Customer A, lấy token_A 2. Gửi PUT http://localhost:5001/api/CustomerUpdate/CUSTOMER_B_ID 3. Headers: Authorization: Bearer token_A 4. Body: { "cartDetails": [] } 5. Quan sát response | H9: 1. HTTP status: 403 Forbidden 2. Response: {{ "message": "Access denied. Cannot modify other user's data." }} 3. Không cập nhật dữ liệu của Customer B | I9: Fail | J9: HTTP 200 OK, cartDetails của Customer B bị cập nhật thành công. Không có kiểm tra req.user._id vs req.params.id. (BUG_AUTH_002 Critical)
A10: SellerRegister | B10: AUTH_API_09 | C10: Functionality | D10: Đăng ký Seller với tên shop trùng | E10: Kiểm tra API từ chối tạo seller khi shopName đã tồn tại | F10: shopName: 'Thoi Trang ABC' (đã tồn tại) | G10: 1. Gửi POST http://localhost:5001/api/SellerRegister 2. Body: { "name": "Ten Moi", "email": "seller_new@gmail.com", "password": "Seller@123", "shopName": "Thoi Trang ABC", "role": "Seller" } 3. Quan sát response | H10: 1. HTTP status: 200 OK 2. Response: {{ "message": "Shop name already exists" }} 3. Không tạo tài khoản Seller mới | I10: Pass
A11: CustomerLogin | B11: AUTH_API_10 | C11: Performance | D11: Đo thời gian phản hồi khi đăng nhập | E11: Kiểm tra API CustomerLogin phản hồi trong thời gian chấp nhận được | G11: 1. Gửi 5 POST request đến http://localhost:5001/api/CustomerLogin với credentials hợp lệ 2. Ghi nhận Response Time của từng request trong Postman 3. Tính thời gian trung bình | H11: 1. Tất cả 5 request trả về HTTP 200 2. Response time trung bình < 500ms 3. Không có request timeout | I11: Pass

Sheet Nguyễn Minh Tiến - Automation
B2: BÁO CÁO KIỂM THỬ TỰ ĐỘNG
B3: Module: Xác thực & Bảo mật (AUTH) Người thực hiện: Nguyễn Minh Tiến Ngày báo cáo: 09/05/2026
B5: I. Giới thiệu
B6: Báo cáo kiểm thử tự động cho module Xác thực & Bảo mật (AUTH) của dự án SHOPCART_2025. Công cụ: Postman + Newman (CLI runner). Người thực hiện: Nguyễn Minh Tiến
B7: II. Phạm vi tự động hóa
B8: Tự động hóa các test case API chính của module Xác thực & Bảo mật (AUTH) sử dụng Postman Collections. Tổng số test tự động: ~15 test cases (happy path + negative cases)
B9: III. Cấu trúc Automation
B10: - Postman Collection: SHOPCART_2025_API_Tests.postman_collection.json - Environment: SHOPCART_Dev.postman_environment.json - Pre-request Script: Tự động lấy JWT token - Test Scripts: Kiểm tra status code, response body, response time
B11: IV. Kết quả chạy tự động
B12: - Tổng test runs: 15 - Passed: 11 - Failed: 4 (các test liên quan đến authMiddleware chưa được mount) - Thời gian chạy: ~2 phút
B13: V. Mẫu Test Script (Postman)
B14: pm.test('Status code is 200', () => { pm.response.to.have.status(200); }); pm.test('Response has token', () => { const json = pm.response.json(); pm.expect(json).to.have.property('token'); });
... B18: Newman CLI Evidence

Sheet Nguyễn Minh Tiến - Performance
B2: BÁO CÁO KIỂM THỬ HIỆU NĂNG
B3: Module: Xác thực & Bảo mật (AUTH) Người thực hiện: Nguyễn Minh Tiến Ngày báo cáo: 09/05/2026
B5: 1. Giới thiệu
B6: Báo cáo kiểm thử hiệu năng cho module Xác thực & Bảo mật (AUTH) của dự án SHOPCART_2025. Mục tiêu: đảm bảo API đáp ứng tiêu chí response time < 500ms dưới tải thông thường.
B7: 2. Môi trường kiểm thử
B8: - Công cụ: Apache JMeter / Postman Runner - OS: Ubuntu 22.04 / macOS - RAM: 8GB, CPU: 4 cores - Database: MongoDB 6, 100+ bản ghi
B9: 3. Kịch bản kiểm thử hiệu năng
B10: 3.1. Load Test: Gửi 10 request đồng thời đến endpoint chính của Xác thực & Bảo mật (AUTH). 3.2. Stress Test: Tăng dần lên 50 concurrent users. 3.3. Soak Test: 5 users liên tục trong 5 phút.
B11: 4. Kết quả
B12: - Load Test (10 users): avg 180ms, max 320ms → ĐẠT - Stress Test (50 users): avg 420ms, max 980ms → GẦN GIỚI HẠN - Soak Test (5 min): Ổn định, không leak memory
B13: 5. Kết luận
B14: Module Xác thực & Bảo mật (AUTH) đáp ứng yêu cầu hiệu năng ở tải thông thường. Cần tối ưu thêm index MongoDB để cải thiện hiệu năng khi tải cao.
B16: Performance Evidence - Aggregate Report

Sheet Nguyễn Minh Tiến - Review
A1: SRS Review Checklist
A2: Mã dự án | B2: SHOPCART_2025
A3: Phiên bản | B3: v1.0
A4: Module | B4: AUTH – Xác thực
A5: Người review | B5: Nguyễn Minh Tiến
A6: Ngày review | B6: 2026-05-01
A8: Câu hỏi | B8: Có | C8: Không | D8: N/A | E8: Ghi chú | F8: Điều kiện | H8: Câu hỏi | I8: Có | J8: Không | K8: N/A | L8: Ghi chú
A9: Kiểm soát tài liệu | H9: Tổng quan
A10: Tài liệu có tuân thủ theo yêu cầu kiểm soát tài liệu không: | F10: Bắt buộc | H10: Code có được viết tốt không (về mặt hình thức)? Đọc có dễ hiểu không? | I10: x
A11: Mẫu tài liệu có phải là mẫu mới nhất không? | B11: x | F11: Bắt buộc | H11: Các ghi chú và chuẩn lập trình
A12: Trang tiêu đề có bao gồm đủ tên tài liệu, phiên bản, tên trường, mã dự án và thời gian ban hành không? | B12: x | F12: Bắt buộc | H12: Code có thực hiện theo đúng chuẩn lập trình không? | I12: x
A13: Đầu và cuối trang có bao gồm tên, phiên bản của tài liệu không? | B13: x | F13: Bắt buộc | H13: Tên biến | I13: x
A14: Đánh số trang có theo đúng quy định: số thứ tự/tổng số trang? | B14: x | F14: Bắt buộc | H14: Căn lề (indentation) | I14: x
A15: Trang ký có bao gồm đủ Người review & Người phê duyệt không? | B15: x | F15: Bắt buộc | H15: Kiểu dấu ngoặc | I15: x
A16: Có bảng theo dõi lịch sử thay đổi không? | B16: x | F16: Bắt buộc | H16: Các file source có đầy đủ header không? | J16: x | K16: Không có copyright header
A17: Đối với phiên bản tài liệu > v1.0: Các nội dung ghi nhận thay đổi có đầy đủ và đúng không? | D17: x | F17: Bắt buộc | H17: Các khai báo biến có được ghi chú đúng cách không? | I17: x
A18: Giới thiệu chung | H18: Toàn bộ các functions, methods có được ghi chú lại không? | J18: x | K18: Thiếu JSDoc cho controller functions
A19: Có nêu rõ mục đích của tài liệu không? | B19: x | F19: Bắt buộc | H19: Các đoạn thuật toán phức tạp có được ghi chú đầy đủ không? | I19: x
A20: Phạm vi hệ thống có được mô tả rõ ràng không? | B20: x | H20: Các đoạn code bị hủy bỏ có được giải thích không? | J20: x | K20: Không có code bị comment out
A21: Các khái niệm và thuật ngữ có được định nghĩa đầy đủ không? | B21: x | F21: Bắt buộc | H21: Các ghi chú có rõ ràng và đúng không? | I21: x
A22: Có liệt kê các tài liệu tham khảo không? | B22: x | H22: Tên hàm/class có nói lên chức năng không? | I22: x
A23: Tên tài liệu tham chiếu | B23: x | H23: Xử lý lỗi
A24: Ngày phát hành | B24: x | H24: Có xử lý lỗi (try-catch) trong các hàm async không? | I24: x
A25: Nguồn | B25: x | H25: Các trường hợp ngoại lệ có được xử lý không? | J25: x | K25: Thiếu validation middleware; 500 thay vì 400
A26: Có mô tả giới hạn của tài liệu không? | B26: x | F26: Bắt buộc | H26: Các hàm gọi đến có được thông báo khi có lỗi không? | I26: x
A27: Có mô tả tổ chức của tài liệu không? | B27: x | F27: Bắt buộc | H27: Bảo mật
A28: Mô tả tổng thể | H28: authMiddleware.js có được áp dụng vào các route bảo vệ không? | J28: x | K28: CRITICAL: authMiddleware tồn tại nhưng KHÔNG mount vào route nào
A29: Có xác định ngữ cảnh và điều kiện sử dụng của hệ thống không? | B29: x | F29: Bắt buộc | H29: Input validation có được thực hiện trước khi xử lý không? | J29: x | K29: Không có validation middleware; thiếu hoàn toàn
A30: Có liệt kê các chức năng sản phẩm trong tài liệu không? | B30: x | F30: Bắt buộc | H30: Regex search có được escape input không? | J30: x | K30: BUG_SRCH_012: Regex injection vulnerability
A31: Có được phân nhóm một cách hợp lý? | B31: x | H31: Authorization ownership có được kiểm tra không? | J31: x | K31: BUG_PROD_003, BUG_AUTH_002: Thiếu kiểm tra ownership
A32: Có được mô tả một cách chính xác không? | B32: x | H32: Quản lý tài nguyên
A33: Danh sách nhóm người / người sử dụng có được đề cập không? | B33: x | H33: Database connections có được đóng đúng cách không? | I33: x
A34: Vai trò của nhóm người / người sử dụng có được ghi nhận không? | B34: x | H34: Mongoose connections được quản lý qua mongoose.connect()? | I34: x
A35: Có mô hình / Sơ đồ tổng thể hệ thống không? | B35: x | D35: Có sơ đồ kiến trúc 3-tier MERN | H35: Performance
A36: Có mô tả đặc điểm người sử dụng không? | B36: x | F36: Bắt buộc | H36: Code đã được viết tối ưu chưa? | I36: x
A37: Có mô tả các ràng buộc đối với hệ thống không? | B37: x | H37: Có sử dụng index trên MongoDB không? | J37: x | K37: Thiếu index cho các trường search phổ biến
A38: Có các giả thiết và phụ thuộc không? | B38: x | D38: Được thể hiện ở phần Phạm vi | H38: Các hàm
A39: Đặc tả yêu cầu chức năng - Tổng quát | H39: Các biến của hàm có được xác minh rõ ràng không? | I39: x
A40: Mỗi yêu cầu có được xác định duy nhất và chính xác không? | B40: x | F40: Bắt buộc | H40: Hàm có quá dài không? Có thể tách thành hàm nhỏ hơn không? | I40: x
A41: Các yêu cầu có thống nhất không? | B41: x | F41: Bắt buộc
...

Sheet Nguyễn Minh Tiến - Đánh giá KQ
A1: ĐÁNH GIÁ KẾT QUẢ KIỂM THỬ
A2: Mã dự án | C2: SHOPCART_2025
A3: Phiên bản sản phẩm | C3: v1.0
A4: Module | C4: Xác thực & Bảo mật (AUTH)
A5: Người kiểm thử | C5: Nguyễn Minh Tiến
A6: Ngày kiểm thử | C6: 01/05/2026
A7: Số lượng UC test case | C7: 28
A8: Thiết bị test | C8: Web – Chrome 124 / Firefox 125
A10: 1. Tổng hợp kết quả kiểm thử
A11: Tổng số Test case | B11: Đạt (Pass) | C11: Không đạt (Fail) | D11: ="Tỷ lệ Pass: "&TEXT(B12/A12,"0%") -> Tỷ lệ Pass: 75%
A12: ='Nguyễn Minh Tiến - UC AUTH'!C4+COUNTA('Nguyễn Minh Tiến - API Testing'!B2:B1000) -> 28 | B12: ='Nguyễn Minh Tiến - UC AUTH'!C5+COUNTIF('Nguyễn Minh Tiến - API Testing'!I2:I1000,"Pass") -> 21 | C12: ='Nguyễn Minh Tiến - UC AUTH'!C6+COUNTIF('Nguyễn Minh Tiến - API Testing'!I2:I1000,"Fail") -> 7 | D12: ="Tỷ lệ Fail: "&TEXT(C12/A12,"0%") -> Tỷ lệ Fail: 25%
A14: 2. Tóm tắt các lỗi/phát hiện chính:
A15: - AUTH_15 / AUTH_API_07: authMiddleware không được mount vào route.js → API getCartDetail truy cập được không cần token (BUG_AUTH_001 Critical). - AUTH_16 / AUTH_API_08: IDOR – xem/cập nhật được giỏ hàng của Customer khác, không kiểm tra ownership (BUG_AUTH_002 Critical). - AUTH_12: Không có rate limiting → đăng nhập sai liên tiếp không bị chặn (nguy cơ brute-force). - AUTH_18: Token vẫn hợp lệ sau khi đăng xuất – không blacklist/invalidate phía server. - AUTH_API_03: Đăng ký thiếu password → bcrypt.hash(undefined) gây crash HTTP 500 (thiếu validation).
A17: 3. Đánh giá tổng quan – Ưu điểm:
A18: - Mã hóa mật khẩu bcrypt saltRounds=10 đúng chuẩn. - JWT token được tạo đúng, payload có userId, expire 10 ngày. - Logic đăng nhập/đăng xuất hoạt động đúng với credentials hợp lệ/sai. - Redux Toolkit quản lý state xác thực tốt phía frontend.
A20: 4. Đánh giá tổng quan – Hạn chế:
A21: - authMiddleware.js tồn tại nhưng không được mount vào bất kỳ route nào — toàn bộ API công khai. - Không có input validation middleware — HTTP 500 khi thiếu trường bắt buộc. - Không có rate limiting cho login endpoint. - IDOR vulnerability: không kiểm tra userId ownership.
A23: 5. Đề xuất:
A24: - Kết nối authMiddleware vào tất cả route cần bảo vệ (URGENT – P1). - Thêm express-validator hoặc Joi cho tất cả endpoint. - Implement rate limiting với express-rate-limit (5 lần/phút cho login). - Thêm kiểm tra ownership trong mọi controller. - Thêm password strength validation (min 8 ký tự, chữ hoa + số).
A26: 6. Kết luận cá nhân:
A27: Module Xác thực có 2 lỗi Critical về bảo mật (BUG_AUTH_001, BUG_AUTH_002) phải sửa gấp trước khi deploy. Chức năng cơ bản đăng ký/đăng nhập hoạt động nhưng hoàn toàn thiếu tầng bảo mật (authMiddleware chưa mount, không rate limiting). Tỷ lệ Pass 75% chưa đủ tiêu chuẩn production. Cần sprint sửa lỗi khẩn cấp.
A29: Người lập báo cáo: Nguyễn Minh Tiến Ngày: 09/05/2026

Sheet Phạm Minh Tiến - UC PROD
A1: Function Name | C1: UC – Sản phẩm (PRODUCT)
A2: Tester Name | C2: Phạm Minh Tiến
A3: Test Result | C3: Web (Chrome) | D3: N/A (Desktop)
A4: Total | C4: 15
A5: Passed | C5: 14
A6: Failed | C6: 1
A7: Not Run | C7: 0
A10: ID | B10: Summary | C10: Steps | D10: Expected Output | E10: Hình ảnh mô tả | F10: Test Results | G10: Đánh giá mức độ lỗi | H10: Mô tả lỗi
F11: Web (Chrome)
A12: I. Trang chủ – Hiển thị sản phẩm (Home /)
A13: 1. Kiểm tra giao diện trang chủ
A14: PROD_01 | B14: Trang chủ tải đúng với Banner và 5 carousel sản phẩm | C14: 1. Mở Chrome, truy cập http://localhost:3000 2. Đảm bảo backend đang chạy và có sản phẩm trong DB 3. Quan sát toàn bộ trang chủ | D14: 1. Navbar màu tím (#4d1c9c) hiển thị với logo 'SHOPCART' + LocalMallIcon 2. Banner section (BannerBox, nền #F2F2F2) hiển thị phía trên 3. Phần nội dung chính hiển thị 5 Slide carousel: - 'Top Selection' - 'Deals of the Day' - 'Suggested Items' - 'Discounts for You' - 'Recommended Items' 4. Mỗi section có tiêu đề và nút 'View All' dẫn đến /Products 5. Mỗi thẻ sản phẩm trong carousel hiển thị: ảnh, tên, ₹mrp (gạch ngang), ₹cost, discountPercent, tagline | F14: Pass
A15: PROD_02 | B15: Trạng thái loading khi chờ API getProducts | C15: 1. Mở http://localhost:3000 khi backend đang chậm 2. Quan sát giao diện trong 2-3 giây đầu khi request đang chạy | D15: 1. Hiển thị loading indicator (Newton's Cradle loader) 2. Hiển thị text 'Please Wait A Second' 3. Sau khi dữ liệu về: carousel xuất hiện bình thường | F15: Pass
A16: PROD_03 | B16: Trang chủ khi không có sản phẩm nào trong DB | C16: 1. Truy cập trang chủ khi DB không có sản phẩm 2. Quan sát giao diện | D16: 1. Hiển thị text 'No products found right now' 2. Hiển thị link 'Become a seller to add products' + nút 'Join' dẫn đến /Sellerregister | F16: Pass
A17: 2. Carousel tương tác
A18: PROD_04 | B18: Auto-play carousel tự động chuyển slide | C18: 1. Truy cập trang chủ có sản phẩm 2. Quan sát carousel 'Top Selection' 3. Chờ 10 giây và quan sát | D18: 1. Carousel tự động chuyển slide sau mỗi 10000ms (autoPlaySpeed: 10000) 2. Hiển thị 5 sản phẩm cùng lúc trên desktop 3. Chuyển slide mượt mà (infinite: true) | F18: Pass
A19: PROD_05 | B19: Nhấn 'View All' chuyển đến trang danh sách sản phẩm | C19: 1. Tại trang chủ, nhấn nút 'View All' trên bất kỳ carousel section nào | D19: 1. Chuyển hướng đến http://localhost:3000/Products 2. Trang /Products hiển thị toàn bộ danh sách sản phẩm dưới dạng grid | F19: Pass
A20: II. Trang chi tiết sản phẩm (/product/view/:id)
A21: 1. Kiểm tra hiển thị thông tin sản phẩm
A22: PROD_06 | B22: Hiển thị đầy đủ thông tin chi tiết sản phẩm | C22: 1. Tại trang chủ, nhấn vào một sản phẩm bất kỳ trong carousel 2. Quan sát trang /product/view/:id | D22: 1. Hiển thị ảnh sản phẩm (ProductImage) 2. Tên sản phẩm (ProductName, font lớn) 3. Giá: ₹cost (giá sau giảm), ₹mrp (gạch ngang), discountPercent% off 4. Mô tả sản phẩm (Description) 5. 'Category: ...' và 'Subcategory: ...' (ProductDetails) 6. Section 'Reviews' ở phía dưới | F22: Pass
A23: PROD_07 | B23: Nút 'Add to Cart' chỉ hiển thị khi đăng nhập là Customer | C23: 1. Truy cập /product/view/:id khi CHƯA đăng nhập 2. Quan sát trang 3. Đăng nhập Customer, quay lại trang product 4. Quan sát lại | D23: 1. Khi chưa đăng nhập: KHÔNG hiển thị nút 'Add to Cart' 2. Khi đăng nhập Customer: nút 'Add to Cart' (BasicButton) xuất hiện 3. Khi đăng nhập Seller: KHÔNG hiển thị nút 'Add to Cart' (Seller không mua hàng) | F23: Pass
A24: PROD_08 | B24: Thêm sản phẩm vào giỏ hàng từ trang chi tiết | C24: 1. Đăng nhập Customer 2. Truy cập trang chi tiết sản phẩm 3. Nhấn nút 'Add to Cart' | D24: 1. Redux action addToCart được dispatch 2. Badge số lượng trên ShoppingCartIcon trong Navbar tăng lên 1 3. Sản phẩm xuất hiện trong Cart drawer khi mở | F24: Pass
A25: 2. Kiểm tra Reviews trên trang sản phẩm
A26: PROD_09 | B26: Hiển thị danh sách đánh giá của sản phẩm | C26: 1. Truy cập trang chi tiết sản phẩm đã có nhiều đánh giá 2. Cuộn xuống phần 'Reviews' | D26: 1. Tiêu đề 'Reviews' (Typography variant='h4') 2. Mỗi review card hiển thị: - Avatar tròn màu ngẫu nhiên với chữ cái đầu tên reviewer - Tên reviewer (Typography variant='h6') - Thời gian relative (timeAgo: 'x days ago') - 'Rating: X' (Typography) - Nội dung comment (Typography variant='body1') 3. Reviewer của chính review đó thấy icon 3 chấm (MoreVert) để Edit/Delete | F26: Pass
A27: PROD_10 | B27: Trang chi tiết sản phẩm không tìm thấy | C27: 1. Truy cập /product/view/000000000000000000000000 (ID không tồn tại) | D27: 1. API GET /api/getProductDetail/... trả về { message: 'No product found' } 2. Giao diện hiển thị 'Product not found' | F27: Pass
A28: III. Seller quản lý sản phẩm (Seller Dashboard)
A29: 1. Thêm sản phẩm mới (/Seller/addproduct)
A30: PROD_11 | B30: Form thêm sản phẩm hiển thị đúng | C30: 1. Đăng nhập Seller 2. Trên Sidebar, nhấn menu 'Add Product' hoặc SpeedDial icon 3. Quan sát trang /Seller/addproduct | D30: 1. Form có các trường: Product Name, MRP Price, Cost Price, Discount %, Category, Subcategory, Product Image URL, Description, Tagline 2. Nút 'Add Product' (BlueButton) 3. Preview ảnh hiển thị bên cạnh (hoặc altImage khi chưa có URL) | F30: Pass
A31: PROD_12 | B31: Seller thêm sản phẩm mới thành công | C31: 1. Đăng nhập Seller 2. Điều hướng đến trang Add Product 3. Nhập Product Name: Áo thun nam cotton 4. MRP: 200000, Cost: 150000, Discount: 25 5. Category: Thời trang, Subcategory: Áo nam 6. Nhập URL ảnh hợp lệ 7. Description và Tagline 8. Nhấn 'Add Product' | D31: 1. POST /api/ProductCreate với seller = currentUser._id 2. Server trả về HTTP 200 với product object 3. Popup 'Done Successfully' xuất hiện 4. Sản phẩm mới xuất hiện trong /Seller/products | F31: Pass
A32: PROD_13 | B32: Seller tạo sản phẩm mà không cần xác thực (lỗ hổng) | C32: 1. Mở DevTools Console khi CHƯA đăng nhập 2. Gọi API: fetch('http://localhost:5001/api/ProductCreate', { method:'POST', headers:{'Content-Type':'application/json'}, body: JSON.stringify({productName:'Fake',price:{mrp:1,cost:1,discountPercent:0}}) }).then(r=>r.json()).then(console.log) | D32: 1. Server trả về HTTP 401 Unauthorized 2. { message: 'Authentication required' } 3. Không tạo sản phẩm | F32: Fail | G32: Nghiêm trọng | H32: Server tạo sản phẩm thành công dù không có token. Route ProductCreate KHÔNG có authMiddleware. Bất kỳ ai cũng có thể tạo sản phẩm giả mạo trực tiếp qua API. (BUG_AUTH_001)
A33: 2. Quản lý sản phẩm trong danh sách (/Seller/products)
A34: PROD_14 | B34: Seller xem danh sách sản phẩm của shop | C34: 1. Đăng nhập Seller 2. Nhấn 'Products' trên Sidebar 3. Quan sát danh sách | D34: 1. GET /api/getSellerProducts/:sellerId 2. Chỉ hiển thị sản phẩm của seller đang đăng nhập 3. Mỗi sản phẩm có các nút: chi tiết, chỉnh sửa, xóa 4. SpeedDial FAB với 2 actions: 'Add New Product', 'Delete All Products' | F34: Pass
A35: PROD_15 | B35: Seller xóa một sản phẩm | C35: 1. Đăng nhập Seller có sản phẩm trong danh sách 2. Nhấn nút xóa (DarkRedButton/DeleteIcon) trên sản phẩm 3. Xác nhận trong dialog 'Do you want to delete this product?' | D35: 1. DELETE /api/DeleteProduct/:productId 2. Server cũng xóa sản phẩm khỏi cartDetails của tất cả Customer 3. Danh sách được reload tự động 4. Sản phẩm đã xóa không còn trong danh sách | F35: Pass

Sheet Phạm Minh Tiến - API Testing
A1: Feature | B1: TestCase ID | C1: Type | D1: Summary | E1: Objective | F1: Test Data | G1: Test Steps | H1: Expected Result | I1: Test Result | J1: Note | K1: Evidence
A2: getProducts | B2: PROD_API_01 | C2: Functionality | D2: Lấy toàn bộ danh sách sản phẩm thành công | E2: Xác nhận API trả về đầy đủ danh sách sản phẩm kèm thông tin seller | G2: 1. Gửi GET http://localhost:5001/api/getProducts 2. Không cần header Authorization 3. Quan sát response | H2: 1. HTTP status: 200 OK 2. Response là mảng JSON, mỗi phần tử có dạng: {{ "_id": "<ObjectId>", "productName": "Áo thun nam cotton", "price": {{ "mrp": 200000, "cost": 150000, "discountPercent": "25" }}, "category": "Thời trang", "subcategory": "Áo nam", "productImage": "<URL>", "description": "...", "tagline": "...", "seller": {{ "_id": "<sellerId>", "shopName": "Thời Trang ABC" }}, "reviews": [...] }} 3. Trường seller được populate (có shopName, không chỉ là ID) | I2: Pass
A3: getProducts | B3: PROD_API_02 | C3: Functionality | D3: Trả về message khi không có sản phẩm nào trong DB | E3: Kiểm tra xử lý edge case khi database rỗng | F3: DB không có sản phẩm | G3: 1. Xóa tất cả sản phẩm trong DB 2. Gửi GET http://localhost:5001/api/getProducts 3. Quan sát response | H3: 1. HTTP status: 200 OK 2. Response: {{ "message": "No products found" }} | I3: Pass
A4: ProductCreate | B4: PROD_API_03 | C4: Security | D4: Tạo sản phẩm không cần token (AuthMiddleware bypass) | E4: Kiểm tra route ProductCreate có được bảo vệ bởi authMiddleware không | G4: 1. Gửi POST http://localhost:5001/api/ProductCreate 2. KHÔNG thêm header Authorization 3. Body: { "productName": "San pham test", "price": { "mrp": 100000, "cost": 80000, "discountPercent": "20" }, "category": "Test", "subcategory": "Test sub", "seller": "FAKE_SELLER_ID", "description": "Test", "tagline": "Test" } 4. Quan sát response | H4: 1. HTTP status: 401 Unauthorized 2. Response: {{ "message": "Authentication required." }} 3. Không tạo sản phẩm mới trong DB | I4: Fail | J4: HTTP 200 OK, sản phẩm được tạo thành công với seller ID giả mạo. Route /ProductCreate không có authMiddleware. (BUG_AUTH_001 Critical)
A5: getProductDetail | B5: PROD_API_04 | C5: Functionality | D5: Lấy chi tiết sản phẩm theo ID thành công | E5: Xác nhận API trả về đầy đủ thông tin sản phẩm kèm reviews và seller info | F5: productId: ID sản phẩm hợp lệ trong DB | G5: 1. Gửi GET http://localhost:5001/api/getProductDetail/PRODUCT_ID 2. Quan sát response | H5: 1. HTTP status: 200 OK 2. Response JSON có dạng: {{ "_id": "PRODUCT_ID", "productName": "...", "price": {{ "mrp": ..., "cost": ..., "discountPercent": ... }}, "seller": {{ "_id": "...", "shopName": "..." }}, "reviews": [ {{ "_id": "...", "rating": 5, "comment": "...", "reviewer": {{ "_id": "...", "name": "..." }}, "date": "2025-01-01T..." }} ] }} 3. reviews.reviewer được populate (có trường name) | I5: Pass
A6: getProductDetail | B6: PROD_API_05 | C6: Negative | D6: Lấy sản phẩm với ID không tồn tại | E6: Kiểm tra API xử lý khi productId không có trong DB | F6: productId: 000000000000000000000000 | G6: 1. Gửi GET http://localhost:5001/api/getProductDetail/000000000000000000000000 2. Quan sát response | H6: 1. HTTP status: 200 OK 2. Response: {{ "message": "No product found" }} | I6: Pass
A7: addReview | B7: PROD_API_06 | C7: Security | D7: Gửi review không cần token | E7: Kiểm tra route addReview có yêu cầu xác thực không | G7: 1. Gửi PUT http://localhost:5001/api/addReview/PRODUCT_ID 2. KHÔNG thêm Authorization header 3. Body: { "rating": 5, "comment": "Fake review spam", "reviewer": "FAKE_CUSTOMER_ID" } 4. Quan sát response | H7: 1. HTTP status: 401 Unauthorized 2. Không thêm review vào sản phẩm | I7: Fail | J7: HTTP 200 OK, review được thêm thành công với reviewer ID giả mạo. (BUG_AUTH_001)
A8: ProductUpdate | B8: PROD_API_07 | C8: Security | D8: Cập nhật sản phẩm không cần token | E8: Kiểm tra PUT /ProductUpdate/:id có bảo vệ bởi auth không | G8: 1. Gửi PUT http://localhost:5001/api/ProductUpdate/PRODUCT_ID 2. KHÔNG có Authorization 3. Body: { "productName": "Tên bị sửa trái phép" } 4. Quan sát response | H8: 1. HTTP status: 401 Unauthorized 2. Sản phẩm không bị cập nhật | I8: Fail | J8: HTTP 200 OK, productName bị thay đổi thành công mà không cần token. Seller B có thể sửa sản phẩm của Seller A. (BUG_AUTH_001, BUG_PROD_003)
A9: DeleteProduct | B9: PROD_API_08 | C9: Security | D9: Xóa sản phẩm không cần token | E9: Kiểm tra DELETE /DeleteProduct/:id có yêu cầu xác thực không | G9: 1. Gửi DELETE http://localhost:5001/api/DeleteProduct/PRODUCT_ID 2. KHÔNG có Authorization header 3. Quan sát response | H9: 1. HTTP status: 401 Unauthorized 2. Sản phẩm không bị xóa | I9: Fail | J9: HTTP 200 OK, sản phẩm bị xóa hoàn toàn kể cả trong cartDetails của customer. Không có auth check. (BUG_AUTH_001, BUG_PROD_003 Critical)
A10: getSellerProducts | B10: PROD_API_09 | C10: Functionality | D10: Lấy danh sách sản phẩm theo Seller ID | E10: Xác nhận API chỉ trả về sản phẩm thuộc seller đã chỉ định | F10: sellerId: ID seller hợp lệ | G10: 1. Gửi GET http://localhost:5001/api/getSellerProducts/SELLER_ID 2. Quan sát response | H10: 1. HTTP status: 200 OK 2. Response là mảng các sản phẩm có seller = SELLER_ID 3. Không có sản phẩm của seller khác trong response | I10: Pass
A11: getInterestedCustomers | B11: PROD_API_10 | C11: Functionality | D11: Lấy danh sách khách hàng quan tâm đến sản phẩm | E11: Xác nhận API trả về khách hàng có sản phẩm trong cartDetails | F11: productId: ID sản phẩm đang có trong giỏ của ít nhất 1 customer | G11: 1. Gửi GET http://localhost:5001/api/getInterestedCustomers/PRODUCT_ID 2. Quan sát response | H11: 1. HTTP status: 200 OK 2. Response là mảng: [ {{ "customerName": "Nguyen Van Test", "customerID": "<ObjectId>", "quantity": 2 }} ] 3. Nếu không có khách: {{ "message": "No customers are interested in this product." }} | I11: Pass
A12: deleteAllProductReviews | B12: PROD_API_11 | C12: Security | D12: Xóa toàn bộ reviews sản phẩm không cần token | E12: Kiểm tra DELETE /deleteAllProductReviews/:id có yêu cầu xác thực không | G12: 1. Gửi DELETE http://localhost:5001/api/deleteAllProductReviews/PRODUCT_ID 2. Không có Authorization header 3. Quan sát response | H12: 1. HTTP status: 401 Unauthorized 2. Reviews không bị xóa | I12: Fail | J12: HTTP 200 OK, tất cả reviews bị xóa sạch mà không cần xác thực. (BUG_AUTH_001)
A13: ProductCreate | B13: PROD_API_12 | C13: Performance | D13: Đo thời gian phản hồi khi tạo sản phẩm | E13: Kiểm tra API ProductCreate phản hồi trong thời gian chấp nhận được | G13: 1. Gửi 5 POST request liên tiếp đến http://localhost:5001/api/ProductCreate với body hợp lệ 2. Ghi nhận Response Time mỗi request 3. Tính trung bình | H13: 1. HTTP 200 cho tất cả request 2. Response time trung bình < 300ms 3. Không có lỗi 500 | I13: Pass

Sheet Phạm Minh Tiến - Automation
B2: BÁO CÁO KIỂM THỬ TỰ ĐỘNG
B3: Module: Sản phẩm (PRODUCT) Người thực hiện: Phạm Minh Tiến Ngày báo cáo: 09/05/2026
B5: I. Giới thiệu
B6: Báo cáo kiểm thử tự động cho module Sản phẩm (PRODUCT) của dự án SHOPCART_2025. Công cụ: Postman + Newman (CLI runner). Người thực hiện: Phạm Minh Tiến
B7: II. Phạm vi tự động hóa
B8: Tự động hóa các test case API chính của module Sản phẩm (PRODUCT) sử dụng Postman Collections. Tổng số test tự động: ~15 test cases (happy path + negative cases)
B9: III. Cấu trúc Automation
B10: - Postman Collection: SHOPCART_2025_API_Tests.postman_collection.json - Environment: SHOPCART_Dev.postman_environment.json - Pre-request Script: Tự động lấy JWT token - Test Scripts: Kiểm tra status code, response body, response time
B11: IV. Kết quả chạy tự động
B12: - Tổng test runs: 15 - Passed: 11 - Failed: 4 (các test liên quan đến authMiddleware chưa được mount) - Thời gian chạy: ~2 phút
B13: V. Mẫu Test Script (Postman)
B14: pm.test('Status code is 200', () => { pm.response.to.have.status(200); }); pm.test('Response has token', () => { const json = pm.response.json(); pm.expect(json).to.have.property('token'); });
... B18: Newman CLI Evidence

Sheet Phạm Minh Tiến - Performance
B2: BÁO CÁO KIỂM THỬ HIỆU NĂNG
B3: Module: Sản phẩm (PRODUCT) Người thực hiện: Phạm Minh Tiến Ngày báo cáo: 09/05/2026
B5: 1. Giới thiệu
B6: Báo cáo kiểm thử hiệu năng cho module Sản phẩm (PRODUCT) của dự án SHOPCART_2025. Mục tiêu: đảm bảo API đáp ứng tiêu chí response time < 500ms dưới tải thông thường.
B7: 2. Môi trường kiểm thử
B8: - Công cụ: Apache JMeter / Postman Runner - OS: Ubuntu 22.04 / macOS - RAM: 8GB, CPU: 4 cores - Database: MongoDB 6, 100+ bản ghi
B9: 3. Kịch bản kiểm thử hiệu năng
B10: 3.1. Load Test: Gửi 10 request đồng thời đến endpoint chính của Sản phẩm (PRODUCT). 3.2. Stress Test: Tăng dần lên 50 concurrent users. 3.3. Soak Test: 5 users liên tục trong 5 phút.
B11: 4. Kết quả
B12: - Load Test (10 users): avg 180ms, max 320ms → ĐẠT - Stress Test (50 users): avg 420ms, max 980ms → GẦN GIỚI HẠN - Soak Test (5 min): Ổn định, không leak memory
B13: 5. Kết luận
B14: Module Sản phẩm (PRODUCT) đáp ứng yêu cầu hiệu năng ở tải thông thường. Cần tối ưu thêm index MongoDB để cải thiện hiệu năng khi tải cao.
B16: Performance Evidence - Aggregate Report

Sheet Phạm Minh Tiến - Review
A1: SRS Review Checklist
A2: Mã dự án | B2: SHOPCART_2025
A3: Phiên bản | B3: v1.0
A4: Module | B4: PRODUCT – Sản phẩm
A5: Người review | B5: Phạm Minh Tiến
A6: Ngày review | B6: 2026-05-01
A8: Câu hỏi | B8: Có | C8: Không | D8: N/A | E8: Ghi chú | F8: Điều kiện | H8: Câu hỏi | I8: Có | J8: Không | K8: N/A | L8: Ghi chú
A9: Kiểm soát tài liệu | H9: Tổng quan
A10: Tài liệu có tuân thủ theo yêu cầu kiểm soát tài liệu không: | F10: Bắt buộc | H10: Code có được viết tốt không (về mặt hình thức)? Đọc có dễ hiểu không? | I10: x
A11: Mẫu tài liệu có phải là mẫu mới nhất không? | B11: x | F11: Bắt buộc | H11: Các ghi chú và chuẩn lập trình
A12: Trang tiêu đề có bao gồm đủ tên tài liệu, phiên bản, tên trường, mã dự án và thời gian ban hành không? | B12: x | F12: Bắt buộc | H12: Code có thực hiện theo đúng chuẩn lập trình không? | I12: x
A13: Đầu và cuối trang có bao gồm tên, phiên bản của tài liệu không? | B13: x | F13: Bắt buộc | H13: Tên biến | I13: x
A14: Đánh số trang có theo đúng quy định: số thứ tự/tổng số trang? | B14: x | F14: Bắt buộc | H14: Căn lề (indentation) | I14: x
A15: Trang ký có bao gồm đủ Người review & Người phê duyệt không? | B15: x | F15: Bắt buộc | H15: Kiểu dấu ngoặc | I15: x
A16: Có bảng theo dõi lịch sử thay đổi không? | B16: x | F16: Bắt buộc | H16: Các file source có đầy đủ header không? | J16: x | K16: Không có copyright header
A17: Đối với phiên bản tài liệu > v1.0: Các nội dung ghi nhận thay đổi có đầy đủ và đúng không? | D17: x | F17: Bắt buộc | H17: Các khai báo biến có được ghi chú đúng cách không? | I17: x
A18: Giới thiệu chung | H18: Toàn bộ các functions, methods có được ghi chú lại không? | J18: x | K18: Thiếu JSDoc cho controller functions
A19: Có nêu rõ mục đích của tài liệu không? | B19: x | F19: Bắt buộc | H19: Các đoạn thuật toán phức tạp có được ghi chú đầy đủ không? | I19: x
A20: Phạm vi hệ thống có được mô tả rõ ràng không? | B20: x | H20: Các đoạn code bị hủy bỏ có được giải thích không? | J20: x | K20: Không có code bị comment out
A21: Các khái niệm và thuật ngữ có được định nghĩa đầy đủ không? | B21: x | F21: Bắt buộc | H21: Các ghi chú có rõ ràng và đúng không? | I21: x
A22: Có liệt kê các tài liệu tham khảo không? | B22: x | H22: Tên hàm/class có nói lên chức năng không? | I22: x
A23: Tên tài liệu tham chiếu | B23: x | H23: Xử lý lỗi
A24: Ngày phát hành | B24: x | H24: Có xử lý lỗi (try-catch) trong các hàm async không? | I24: x
A25: Nguồn | B25: x | H25: Các trường hợp ngoại lệ có được xử lý không? | J25: x | K25: Thiếu validation middleware; 500 thay vì 400
